Workbook

Sheet 🏆 SUMMARY
A1: MF INTELLIGENCE — ASSET CLASS RANKED SUMMARY
A2: ="Top Performer per Asset Class | 55% Momentum + 45% Quality | Total Asset Classes: "&COUNTA(B5:B18)&" | ⭐ Strong Buy+: "&COUNTIF(Q5:Q18,"*Strong*")
F3: ◄ Momentum ► | I3: ◄ Long-Term ► | L3: ◄ Engine Scores ► | O3: ◄ Signals ►
A4: Rank | B4: Asset Class | C4: Top Scheme | D4: AMC | E4: Category | F4: 1M Return | G4: 3M Return | H4: 6M Return | I4: 1Y Return | J4: 2Y CAGR | K4: 3Y CAGR | L4: Engine 1 (Momentum) | M4: Engine 2 (Quality) | N4: Composite Score | O4: Momentum Signal | P4: Quality Signal | Q4: Composite Signal
A5: 1 | B5: Banking/Financial | C5: DSP Nifty PSU Bank ETF | D5: DSP Mutual Fund | E5: Other Etfs | F5: 2.81 | G5: 8.63 | H5: -9.91 | I5: 23.42 | J5: 12.738636 | K5: 89.58 | L5: 61.9 | M5: 31.9 | N5: 48.4 | O5: 📈 Good | P5: ⚠️ Below Avg | Q5: ⚠️ Watch
A6: 2 | B6: Commodities | C6: ICICI Prudential Strategic Metal and Energy Equity Fund of Fund - Growth | D6: ICICI Prudential Mutual Fund | E6: Fof Overseas | F6: 13.94 | G6: 4.49 | H6: 14.37 | I6: 74.53 | J6: 45.14131 | K6: 145.47 | L6: 80.2 | M6: 94.9 | N6: 86.8 | O6: ⭐ Strong | P6: 🏆 Elite | Q6: ⭐ Strong Buy
A7: 3 | B7: G-SEC | C7: HDFC Nifty G-Sec Sep 2032 Index Fund - Growth Option | D7: HDFC Mutual Fund | E7: Index Funds | F7: 0.62 | G7: 3.92 | H7: 3.25 | I7: 5.66 | J7: 7.3964618 | K7: 25.72 | L7: 62.2 | M7: 0 | N7: 34.2 | O7: 📈 Good | P7: 🔴 Not Qualified | Q7: 🔴 Avoid
A8: 4 | B8: GILT | C8: BANDHAN CRISIL IBX GILT APRIL 2032 INDEX FUND - REGULAR GROWTH | D8: Bandhan Mutual Fund | E8: Index Funds | F8: 0.49 | G8: 3.76 | H8: 3.03 | I8: 5.61 | J8: 7.2800075 | K8: 25.39 | L8: 57.7 | M8: 0 | N8: 31.7 | O8: ➡️ Neutral | P8: 🔴 Not Qualified | Q8: 🔴 Avoid
A9: 5 | B9: Gold | C9: DSP World Gold Mining Overseas Equity Omni FoF - Regular Plan - Growth | D9: DSP Mutual Fund | E9: Fof Overseas | F9: 26.45 | G9: 6.81 | H9: -4.09 | I9: 77.12 | J9: 68.127927 | K9: 287.35 | L9: 64.2 | M9: 99.4 | N9: 80 | O9: 📈 Good | P9: 🏆 Elite | Q9: ⭐ Strong Buy
A10: 6 | B10: Index Fund | C10: Motilal Oswal Nifty Microcap 250 Index Fund- Regular- Growth Option | D10: Motilal Oswal Mutual Fund | E10: Index Funds | F10: 4.94 | G10: 14.96 | H10: 18.85 | I10: 12.52 | J10: 2.7180607 | K10: 69.86 | L10: 100 | M10: 0 | N10: 55 | O10: 🔥 Hot | P10: 🔴 Not Qualified | Q10: ✅ Buy
A11: 7 | B11: Infrastructure | C11: ICICI Prudential Nifty Infrastructure ETF | D11: ICICI Prudential Mutual Fund | E11: Other Etfs | F11: 0.19 | G11: 1.48 | H11: -3.37 | I11: 4.61 | J11: 1.5283212 | K11: 58.4 | L11: 40.7 | M11: 0 | N11: 22.4 | O11: ➡️ Neutral | P11: 🔴 Not Qualified | Q11: 🔴 Avoid
A12: 8 | B12: International | C12: Mirae Asset Global X Artificial Intelligence & Technology ETF Fund of Fund - Regular Plan - Growth | D12: Mirae Asset Mutual Fund | E12: Fof Overseas | F12: 8.14 | G12: 5.08 | H12: 35.91 | I12: 54.1 | J12: 43.443369 | K12: 171.88 | L12: 91.4 | M12: 93.3 | N12: 92.2 | O12: 🔥 Hot | P12: 🏆 Elite | Q12: ⭐ Strong Buy
A13: 9 | B13: NASDAQ | C13: ICICI Prudential NASDAQ 100 Index Fund - Growth | D13: ICICI Prudential Mutual Fund | E13: Index Funds | F13: 4 | G13: 3.08 | H13: 26.6 | I13: 36.72 | J13: 31.689028 | K13: 131.73 | L13: 89.7 | M13: 100 | N13: 94.3 | O13: ⭐ Strong | P13: 🏆 Elite | Q13: ⭐ Strong Buy
A14: 10 | B14: Pharma/Healthcare | C14: Motilal Oswal BSE Healthcare ETF | D14: Motilal Oswal Mutual Fund | E14: Other Etfs | F14: 2.14 | G14: 7.15 | H14: 17.57 | I14: 14.67 | J14: 11.43608 | K14: 84.33 | L14: 87.1 | M14: 13.1 | N14: 53.8 | O14: ⭐ Strong | P14: ⚠️ Below Avg | Q14: ⚠️ Watch
A15: 11 | B15: S&P 500 | C15: Motilal Oswal S&P 500 Index Fund - Regular Plan Growth | D15: Motilal Oswal Mutual Fund | E15: Index Funds | F15: 3.08 | G15: 4.25 | H15: 18.48 | I15: 30.38 | J15: 25.610509 | K15: 102.13 | L15: 93 | M15: 50 | N15: 73.7 | O15: 🔥 Hot | P15: ➡️ Average | Q15: 📈 Momentum Play
A16: 12 | B16: Silver | C16: ICICI PRUDENTIAL SILVER ETF | D16: ICICI Prudential Mutual Fund | E16: Other Etfs | F16: 8.18 | G16: -12.91 | H16: -1.6 | I16: 100.58 | J16: 67.119718 | K16: 220.82 | L16: 66.4 | M16: 97.2 | N16: 80.3 | O16: 📈 Good | P16: 🏆 Elite | Q16: ⭐ Strong Buy
... A18: 14 | B18: Technology | C18: Edelweiss US Technology Equity Fund of Fund- Regular Plan- Growth | D18: Edelweiss Mutual Fund | E18: Fof Overseas | F18: 5.76 | G18: 2.9 | H18: 27.78 | I18: 30.92 | J18: 31.213566 | K18: 129.92 | L18: 72.2 | M18: 68.2 | N18: 70.4 | O18: 📈 Good | P18: 🏛️ Solid | Q18: 📈 Momentum Play

Sheet 📋 ASSUMPTIONS
A1: DUAL ENGINE MODEL — COMPLETE METHODOLOGY & ASSUMPTIONS
A2: Generated: 2026-10-02 23:57:43 | Comprehensive Documentation | All Values Numeric (0 = Missing)
A4: 🔍 DATA FILTERS (Pre-Processing)
A5: Filter Parameter | B5: Value | C5: Description | D5: Python Logic
A6: cat_level_1 | B6: Open Ended Schemes | C6: Scheme category level 1 | D6: df[col] == value
A7: cat_level_2 | B7: Other Scheme | C7: Scheme category level 2 | D7: df[col] == value
A8: plan_type | B8: Regular | C8: Regular plans only (not Direct) | D8: df[col] == value
A9: option_type | B9: Growth | C9: Growth option only | D9: df[col] == value
A11: 📋 COLUMN MAPPING (Source → Internal)
A12: Internal Name | B12: Source Column | C12: Data Type | D12: Notes
A13: scheme_name | B13: scheme_name | C13: String | D13: Fund name for display
A14: category | B14: cat_level_3 | C14: String | D14: Category for grouping
A15: amc | B15: amc_name | C15: String | D15: Asset Management Company
A16: return_1m | B16: return_30d | C16: Numeric % | D16: 30-day return
A17: return_3m | B17: return_90d | C17: Numeric % | D17: 90-day return
A18: return_6m | B18: return_180d | C18: Numeric % | D18: 180-day return
A19: return_1y | B19: return_365d | C19: Numeric % | D19: 365-day return
A20: return_2y | B20: return_730d | C20: Numeric % | D20: 730-day cumulative → CAGR
A21: return_3y | B21: return_1095d | C21: Numeric % | D21: 1095-day CAGR
A23: 📊 DATA STATUS CLASSIFICATION
A24: Status | B24: Condition | C24: Visual Style | D24: Scoring Impact
A25: ✅ FULL | B25: All 1M/3M/6M + 2Y/3Y present | C25: White/Ranked Colors | D25: Both E1 and E2 calculated
A26: ⚠️ MOMENTUM_ONLY | B26: 1M/3M/6M present, 2Y/3Y missing | C26: Light Amber + Italic | D26: Only E1 calculated, E2=0
A27: ❌ MISSING | B27: Missing any of 1M/3M/6M | C27: Light Gray + Italic | D27: E1=0, E2=0, Comp=0
A29: 🚦 QUALITY GATES (Engine 2 Eligibility)
A30: Gate | B30: Threshold | C30: Formula | D30: Purpose
A31: Min 2Y CAGR | B31: 10% | C31: r2y_cagr > 10% | D31: Filter low long-term performers
A32: Min 3Y CAGR | B32: 12% | C32: r3y > 12% | D32: Filter inconsistent performers
A33: Drawdown Tolerance | B33: -30% | C33: r1y > -30% | D33: Exclude extreme losers
A34: Data Status | B34: FULL only | C34: data_status == 'FULL' | D34: Only complete data qualifies
A36: 📈 ENGINE 1: MOMENTUM SCORE (Short-Term)
A37: Component | B37: Weight | C37: Formula | D37: Description
A38: 6M Return Rank | B38: 30% | C38: pct_rank(r6m) × 0.30 | D38: 6-month percentile within category
A39: 3M Return Rank | B39: 20% | C39: pct_rank(r3m) × 0.20 | D39: 3-month percentile within category
A40: 1Y Return Rank | B40: 25% | C40: pct_rank(r1y) × 0.25 | D40: 1-year percentile within category
A41: 1M Return Rank | B41: 25% | C41: pct_rank(r1m) × 0.25 | D41: 1-month percentile within category
A42: Trend Bonus | B42: +5.0 | C42: If r6m > r3m > r1m | D42: 📈 Uptrend bonus (0 to 5 pts)
A43: Final E1 | B43: 0-100 | C43: clip(sum + trend, 0, 100) | D43: Capped percentile score
A45: 🏛️ ENGINE 2: QUALITY SCORE (Long-Term)
A46: Component | B46: Weight | C46: Formula | D46: Description
...

Sheet Fof Domestic
A1: ✦ FOF DOMESTIC ✦
A2: ="Dual Engine: 55% Momentum + 45% Quality | ✅ Full: "&COUNTIF(Q5:Q125,"FULL")&" | ⚠️ Momentum: "&COUNTIF(Q5:Q125,"MOMENTUM_ONLY")&" | ❌ Missing: "&COUNTIF(Q5:Q125,"MISSING")&" | Total: "&COUNTA(B5:B125)
E3: ◄ Momentum ► | H3: ◄ Long-Term ► | K3: ◄ Engine Scores ► | N3: ◄ Signals ►
A4: Rank | B4: Scheme Name | C4: AMC | D4: Asset Class | E4: 1M Return | F4: 3M Return | G4: 6M Return | H4: 1Y Return | I4: 2Y CAGR | J4: 3Y CAGR | K4: Engine 1 (Momentum) | L4: Engine 2 (Quality) | M4: Composite Score | N4: Momentum Signal | O4: Quality Signal | P4: Composite Signal | Q4: Data Status
A5: 1 | B5: UTI Silver ETF Fund of Fund - Regular Plan - Growth Option | C5: UTI Mutual Fund | D5: Silver | E5: 8.06 | F5: -12.55 | G5: -0.96 | H5: 97.72 | I5: 65.00303 | J5: 213.16 | K5: 48.5 | L5: 97.8 | M5: 70.7 | N5: ➡️ Neutral | O5: 🏆 Elite | P5: 🏛️ Quality Hold | Q5: FULL
A6: 2 | B6: Motilal Oswal Nasdaq 100 Fund of Fund- Regular Plan Growth | C6: Motilal Oswal Mutual Fund | D6: NASDAQ | E6: 0.99 | F6: 2.65 | G6: 47.22 | H6: 63.25 | I6: 43.965274 | J6: 176.58 | K6: 77.4 | L6: 57.6 | M6: 68.5 | N6: ⭐ Strong | O6: ➡️ Average | P6: 📈 Momentum Play | Q6: FULL
A7: 3 | B7: Kotak Silver ETF Fund of Fund - Regular Plan - Growth Option | C7: Kotak Mahindra Mutual Fund | D7: Silver | E7: 7.95 | F7: -12.43 | G7: -0.99 | H7: 98.55 | I7: 65.230143 | J7: 209.48 | K7: 48.9 | L7: 91 | M7: 67.9 | N7: ➡️ Neutral | O7: 🏆 Elite | P7: 🏛️ Quality Hold | Q7: FULL
A8: 4 | B8: ICICI Prudential Silver ETF FOF - Growth | C8: ICICI Prudential Mutual Fund | D8: Silver | E8: 8.14 | F8: -12.57 | G8: -0.88 | H8: 97.2 | I8: 64.687583 | J8: 210.94 | K8: 48.4 | L8: 89.6 | M8: 66.9 | N8: ➡️ Neutral | O8: ⭐ Strong | P8: 🏛️ Quality Hold | Q8: FULL
A9: 5 | B9: Axis Silver Fund of Fund -Regular Plan- Growth Option | C9: Axis Mutual Fund | D9: Silver | E9: 7.94 | F9: -12.45 | G9: -0.84 | H9: 97.56 | I9: 64.423234 | J9: 210.68 | K9: 48.9 | L9: 88.4 | M9: 66.7 | N9: ➡️ Neutral | O9: ⭐ Strong | P9: 🏛️ Quality Hold | Q9: FULL
A10: 6 | B10: Edelweiss Gold and Silver ETF FOF - Regular Plan - Growth | C10: Edelweiss Mutual Fund | D10: Silver | E10: 8.94 | F10: -7.63 | G10: 0.26 | H10: 77.66 | I10: 56.789668 | J10: 185.56 | K10: 56.6 | L10: 76 | M10: 65.3 | N10: ➡️ Neutral | O10: ⭐ Strong | P10: 🏛️ Quality Hold | Q10: FULL
A11: 7 | B11: Nippon India Silver ETF FOF-Regular Plan- Growth Option | C11: Nippon India Mutual Fund | D11: Silver | E11: 8.1 | F11: -12.59 | G11: -1.23 | H11: 97.26 | I11: 64.763467 | J11: 210.1 | K11: 47.1 | L11: 87.4 | M11: 65.2 | N11: ➡️ Neutral | O11: ⭐ Strong | P11: 🏛️ Quality Hold | Q11: FULL
A12: 8 | B12: HDFC Silver ETF Fund of Fund - Growth Option | C12: HDFC Mutual Fund | D12: Silver | E12: 8.14 | F12: -12.54 | G12: -1.28 | H12: 97.23 | I12: 64.523555 | J12: 210.58 | K12: 47.3 | L12: 85.8 | M12: 64.6 | N12: ➡️ Neutral | O12: ⭐ Strong | P12: 🏛️ Quality Hold | Q12: FULL
A13: 9 | B13: Aditya Birla Sun Life Gold Fund-Growth | C13: Aditya Birla Sun Life Mutual Fund | D13: Gold | E13: 9.18 | F13: -3.05 | G13: 1.61 | H13: 51.89 | I13: 45.365058 | J13: 152.18 | K13: 71.5 | L13: 55.2 | M13: 64.2 | N13: 📈 Good | O13: ➡️ Average | P13: 📈 Momentum Play | Q13: FULL
A14: 10 | B14: Quantum Gold ETF FOF - Regular Plan Growth Option | C14: Quantum Mutual Fund | D14: Gold | E14: 8.86 | F14: -3.56 | G14: 1.35 | H14: 51.98 | I14: 45.705182 | J14: 153.18 | K14: 62.1 | L14: 65.2 | M14: 63.5 | N14: 📈 Good | O14: 🏛️ Solid | P14: 🏛️ Quality Hold | Q14: FULL
A15: 11 | B15: SBI GOLD FUND REGULAR PLAN - GROWTH | C15: SBI Mutual Fund | D15: Gold | E15: 9.15 | F15: -3.33 | G15: 1.45 | H15: 51.84 | I15: 45.478521 | J15: 152.44 | K15: 67.7 | L15: 57.2 | M15: 63 | N15: 📈 Good | O15: ➡️ Average | P15: 📈 Momentum Play | Q15: FULL
A16: 12 | B16: UTI Gold ETF Fund of Fund - Regular Plan - Growth Opton | C16: UTI Mutual Fund | D16: Gold | E16: 9.07 | F16: -3.34 | G16: 1.41 | H16: 51.7 | I16: 45.653699 | J16: 153.12 | K16: 64.3 | L16: 59.2 | M16: 62 | N16: 📈 Good | O16: ➡️ Average | P16: 📈 Momentum Play | Q16: FULL
... A125: 0 | B125: Mirae Asset BSE India Defence ETF FOF - Regular Plan - Growth | C125: Mirae Asset Mutual Fund | D125: Index Fund | E125: 7.14 | F125: 12.82 | G125: 0 | H125: 0 | I125: 0 | J125: 0 | K125: 0 | L125: 0 | M125: 0 | N125: ❌ N/A | O125: ❌ N/A | P125: ❌ Missing Data | Q125: MISSING

Sheet Fof Overseas
A1: ✦ FOF OVERSEAS ✦
A2: ="Dual Engine: 55% Momentum + 45% Quality | ✅ Full: "&COUNTIF(Q5:Q50,"FULL")&" | ⚠️ Momentum: "&COUNTIF(Q5:Q50,"MOMENTUM_ONLY")&" | ❌ Missing: "&COUNTIF(Q5:Q50,"MISSING")&" | Total: "&COUNTA(B5:B50)
E3: ◄ Momentum ► | H3: ◄ Long-Term ► | K3: ◄ Engine Scores ► | N3: ◄ Signals ►
A4: Rank | B4: Scheme Name | C4: AMC | D4: Asset Class | E4: 1M Return | F4: 3M Return | G4: 6M Return | H4: 1Y Return | I4: 2Y CAGR | J4: 3Y CAGR | K4: Engine 1 (Momentum) | L4: Engine 2 (Quality) | M4: Composite Score | N4: Momentum Signal | O4: Quality Signal | P4: Composite Signal | Q4: Data Status
A5: 1 | B5: Mirae Asset Global X Artificial Intelligence & Technology ETF Fund of Fund - Regular Plan - Growth | C5: Mirae Asset Mutual Fund | D5: International | E5: 8.14 | F5: 5.08 | G5: 35.91 | H5: 54.1 | I5: 43.443369 | J5: 171.88 | K5: 91.4 | L5: 93.3 | M5: 92.2 | N5: 🔥 Hot | O5: 🏆 Elite | P5: ⭐ Strong Buy | Q5: FULL
A6: 2 | B6: ICICI Prudential Strategic Metal and Energy Equity Fund of Fund - Growth | C6: ICICI Prudential Mutual Fund | D6: Commodities | E6: 13.94 | F6: 4.49 | G6: 14.37 | H6: 74.53 | I6: 45.14131 | J6: 145.47 | K6: 80.2 | L6: 94.9 | M6: 86.8 | N6: ⭐ Strong | O6: 🏆 Elite | P6: ⭐ Strong Buy | Q6: FULL
A7: 3 | B7: DSP World Mining Overseas Equity Omni FoF - Regular Plan - Growth | C7: DSP Mutual Fund | D7: International | E7: 15.47 | F7: 4.8 | G7: 4.85 | H7: 77.44 | I7: 45.650266 | J7: 124.33 | K7: 71.5 | L7: 91.2 | M7: 80.3 | N7: 📈 Good | O7: 🏆 Elite | P7: ⭐ Strong Buy | Q7: FULL
A8: 4 | B8: DSP World Gold Mining Overseas Equity Omni FoF - Regular Plan - Growth | C8: DSP Mutual Fund | D8: Gold | E8: 26.45 | F8: 6.81 | G8: -4.09 | H8: 77.12 | I8: 68.127927 | J8: 287.35 | K8: 64.2 | L8: 99.4 | M8: 80 | N8: 📈 Good | O8: 🏆 Elite | P8: ⭐ Strong Buy | Q8: FULL
A9: 5 | B9: Kotak US Specific Equity Passive FOF - Regular Plan - Growth | C9: Kotak Mahindra Mutual Fund | D9: Standard Equity/Debt | E9: 4.71 | F9: 4.11 | G9: 26.74 | H9: 37.91 | I9: 32.332914 | J9: 134.72 | K9: 77 | L9: 79.9 | M9: 78.3 | N9: ⭐ Strong | O9: ⭐ Strong | P9: ⭐ Strong Buy | Q9: FULL
A10: 6 | B10: Edelweiss Emerging Markets Opportunities Equity Offshore Fund - Regular Plan - Growth Option | C10: Edelweiss Mutual Fund | D10: International | E10: 4.35 | F10: 3.24 | G10: 18.23 | H10: 56.11 | I10: 35.558106 | J10: 110.57 | K10: 73.3 | L10: 81.9 | M10: 77.2 | N10: 📈 Good | O10: ⭐ Strong | P10: ⭐ Strong Buy | Q10: FULL
A11: 7 | B11: Axis NASDAQ 100 US Specific Equity Passive FOF - Regular Plan - Growth | C11: Axis Mutual Fund | D11: NASDAQ | E11: 4.68 | F11: 4.15 | G11: 26.34 | H11: 37.4 | I11: 31.78012 | J11: 131.89 | K11: 75 | L11: 76.5 | M11: 75.7 | N11: ⭐ Strong | O11: ⭐ Strong | P11: ⭐ Strong Buy | Q11: FULL
A12: 8 | B12: Navi NASDAQ100 US Specific Equity Passive FOF- Regular- Growth | C12: Navi Mutual Fund | D12: NASDAQ | E12: 4.19 | F12: 3.03 | G12: 27.01 | H12: 37.36 | I12: 32.230859 | J12: 134.87 | K12: 71.4 | L12: 79 | M12: 74.8 | N12: 📈 Good | O12: ⭐ Strong | P12: 🏛️ Quality Hold | Q12: FULL
A13: 9 | B13: DSP US Specific Equity Omni FoF - Regular Plan - Growth Option | C13: DSP Mutual Fund | D13: Standard Equity/Debt | E13: 4.24 | F13: 2.49 | G13: 22.74 | H13: 41.26 | I13: 32.529242 | J13: 111.76 | K13: 70.1 | L13: 76.2 | M13: 72.8 | N13: 📈 Good | O13: ⭐ Strong | P13: 🏛️ Quality Hold | Q13: FULL
A14: 10 | B14: DSP Global Innovation Overseas Equity Omni FoF - Regular - Growth | C14: DSP Mutual Fund | D14: International | E14: 4.92 | F14: 8.02 | G14: 21.17 | H14: 31.73 | I14: 27.71061 | J14: 114.68 | K14: 79.2 | L14: 64.1 | M14: 72.4 | N14: ⭐ Strong | O14: 🏛️ Solid | P14: 📈 Momentum Play | Q14: FULL
A15: 11 | B15: Edelweiss US Technology Equity Fund of Fund- Regular Plan- Growth | C15: Edelweiss Mutual Fund | D15: Technology | E15: 5.76 | F15: 2.9 | G15: 27.78 | H15: 30.92 | I15: 31.213566 | J15: 129.92 | K15: 72.2 | L15: 68.2 | M15: 70.4 | N15: 📈 Good | O15: 🏛️ Solid | P15: 📈 Momentum Play | Q15: FULL
A16: 12 | B16: Axis Global Innovation Fund of Fund - Regular Plan - Growth | C16: Axis Mutual Fund | D16: International | E16: 8.23 | F16: 7.76 | G16: 26.56 | H16: 31.36 | I16: 25.435242 | J16: 104.46 | K16: 83.2 | L16: 54.2 | M16: 70.2 | N16: ⭐ Strong | O16: ➡️ Average | P16: 📈 Momentum Play | Q16: FULL
... A50: 0 | B50: Kotak Quality Overseas Equity Omni FOF - Regular Plan - Growth | C50: Kotak Mahindra Mutual Fund | D50: International | E50: 3.39 | F50: 5.2 | G50: 0 | H50: 0 | I50: 0 | J50: 0 | K50: 0 | L50: 0 | M50: 0 | N50: ❌ N/A | O50: ❌ N/A | P50: ❌ Missing Data | Q50: MISSING

Sheet Gold Etf
A1: ✦ GOLD ETF ✦
A2: ="Dual Engine: 55% Momentum + 45% Quality | ✅ Full: "&COUNTIF(Q5:Q27,"FULL")&" | ⚠️ Momentum: "&COUNTIF(Q5:Q27,"MOMENTUM_ONLY")&" | ❌ Missing: "&COUNTIF(Q5:Q27,"MISSING")&" | Total: "&COUNTA(B5:B27)
E3: ◄ Momentum ► | H3: ◄ Long-Term ► | K3: ◄ Engine Scores ► | N3: ◄ Signals ►
A4: Rank | B4: Scheme Name | C4: AMC | D4: Asset Class | E4: 1M Return | F4: 3M Return | G4: 6M Return | H4: 1Y Return | I4: 2Y CAGR | J4: 3Y CAGR | K4: Engine 1 (Momentum) | L4: Engine 2 (Quality) | M4: Composite Score | N4: Momentum Signal | O4: Quality Signal | P4: Composite Signal | Q4: Data Status
A5: 1 | B5: Quantum Gold ETF | C5: Quantum Mutual Fund | D5: Gold | E5: 9.05 | F5: -3.16 | G5: 1.31 | H5: 52.76 | I5: 46.584447 | J5: 156.52 | K5: 66.1 | L5: 88.9 | M5: 76.3 | N5: 📈 Good | O5: ⭐ Strong | P5: ⭐ Strong Buy | Q5: FULL
A6: 2 | B6: UTI GOLD Exchange Traded Fund | C6: UTI Mutual Fund | D6: Gold | E6: 9.06 | F6: -3.16 | G6: 1.11 | H6: 52.86 | I6: 46.696967 | J6: 158.67 | K6: 55.6 | L6: 100 | M6: 75.6 | N6: ➡️ Neutral | O6: 🏆 Elite | P6: ⭐ Strong Buy | Q6: FULL
A7: 3 | B7: ICICI Prudential Gold ETF | C7: ICICI Prudential Mutual Fund | D7: Gold | E7: 8.99 | F7: -3.13 | G7: 1.32 | H7: 52.43 | I7: 46.280552 | J7: 156.05 | K7: 65.6 | L7: 72.8 | M7: 68.8 | N7: 📈 Good | O7: 🏛️ Solid | P7: 🏛️ Quality Hold | Q7: FULL
A8: 4 | B8: KOTAK GOLD ETF | C8: Kotak Mahindra Mutual Fund | D8: Gold | E8: 9.04 | F8: -3.14 | G8: 1.32 | H8: 52.34 | I8: 46.123236 | J8: 155.52 | K8: 68.2 | L8: 56.7 | M8: 63 | N8: 📈 Good | O8: ➡️ Average | P8: 📈 Momentum Play | Q8: FULL
A9: 5 | B9: Mirae Asset Gold ETF | C9: Mirae Asset Mutual Fund | D9: Gold | E9: 8.98 | F9: -3.1 | G9: 1.38 | H9: 52.17 | I9: 46.044514 | J9: 155.48 | K9: 72.3 | L9: 33.3 | M9: 54.7 | N9: 📈 Good | O9: ⚠️ Below Avg | P9: ⚠️ Watch | Q9: FULL
A10: 6 | B10: DSP Gold ETF | C10: DSP Mutual Fund | D10: Gold | E10: 8.99 | F10: -3.11 | G10: 1.34 | H10: 52.3 | I10: 46.054784 | J10: 155.14 | K10: 68.9 | L10: 37.2 | M10: 54.7 | N10: 📈 Good | O10: ⚠️ Below Avg | P10: ⚠️ Watch | Q10: FULL
A11: 7 | B11: HDFC Gold ETF - Growth Option | C11: HDFC Mutual Fund | D11: Gold | E11: 9.02 | F11: -3.16 | G11: 1.28 | H11: 52.29 | I11: 45.886943 | J11: 156.11 | K11: 53.7 | L11: 49.4 | M11: 51.8 | N11: ➡️ Neutral | O11: ➡️ Average | P11: ⚠️ Watch | Q11: FULL
A12: 8 | B12: Tata Gold Exchange Traded Fund | C12: Tata Mutual Fund | D12: Gold | E12: 8.95 | F12: -3.08 | G12: 1.38 | H12: 52.36 | I12: 46.119814 | J12: 0 | K12: 75.1 | L12: 0 | M12: 41.3 | N12: ⭐ Strong | O12: ⏳ New Fund | P12: 📈 Momentum Only | Q12: MOMENTUM_ONLY
A13: 9 | B13: Axis Gold ETF | C13: Axis Mutual Fund | D13: Gold | E13: 8.98 | F13: -3.19 | G13: 1.15 | H13: 52.07 | I13: 46.058208 | J13: 156.04 | K13: 31.3 | L13: 44.4 | M13: 37.2 | N13: 📉 Weak | O13: ➡️ Average | P13: 🔴 Avoid | Q13: FULL
A14: 10 | B14: 360 ONE Gold ETF | C14: 360 ONE Mutual Fund | D14: Gold | E14: 8.95 | F14: -3.08 | G14: 1.37 | H14: 51.35 | I14: 0 | J14: 0 | K14: 59.4 | L14: 0 | M14: 32.7 | N14: ➡️ Neutral | O14: ⏳ New Fund | P14: ⏳ New Fund | Q14: MOMENTUM_ONLY
A15: 11 | B15: Zerodha Gold ETF | C15: Zerodha Mutual Fund | D15: Gold | E15: 9.11 | F15: -3.16 | G15: 1.27 | H15: 52.36 | I15: 46.133501 | J15: 0 | K15: 57.7 | L15: 0 | M15: 31.8 | N15: ➡️ Neutral | O15: ⏳ New Fund | P15: ⏳ New Fund | Q15: MOMENTUM_ONLY
A16: 12 | B16: The Wealth Company Gold ETF | C16: The Wealth Company Mutual Fund | D16: Gold | E16: 8.79 | F16: -2.97 | G16: 1.42 | H16: 0 | I16: 0 | J16: 0 | K16: 53.7 | L16: 0 | M16: 29.5 | N16: ➡️ Neutral | O16: ⏳ New Fund | P16: ⏳ New Fund | Q16: MOMENTUM_ONLY
... A27: 0 | B27: HSBC Gold ETF | C27: HSBC Mutual Fund | D27: Gold | E27: 8.88 | F27: -3.12 | G27: 0 | H27: 0 | I27: 0 | J27: 0 | K27: 0 | L27: 0 | M27: 0 | N27: ❌ N/A | O27: ❌ N/A | P27: ❌ Missing Data | Q27: MISSING

Sheet Index Funds
A1: ✦ INDEX FUNDS ✦
A2: ="Dual Engine: 55% Momentum + 45% Quality | ✅ Full: "&COUNTIF(Q5:Q346,"FULL")&" | ⚠️ Momentum: "&COUNTIF(Q5:Q346,"MOMENTUM_ONLY")&" | ❌ Missing: "&COUNTIF(Q5:Q346,"MISSING")&" | Total: "&COUNTA(B5:B346)
E3: ◄ Momentum ► | H3: ◄ Long-Term ► | K3: ◄ Engine Scores ► | N3: ◄ Signals ►
A4: Rank | B4: Scheme Name | C4: AMC | D4: Asset Class | E4: 1M Return | F4: 3M Return | G4: 6M Return | H4: 1Y Return | I4: 2Y CAGR | J4: 3Y CAGR | K4: Engine 1 (Momentum) | L4: Engine 2 (Quality) | M4: Composite Score | N4: Momentum Signal | O4: Quality Signal | P4: Composite Signal | Q4: Data Status
A5: 1 | B5: ICICI Prudential NASDAQ 100 Index Fund - Growth | C5: ICICI Prudential Mutual Fund | D5: NASDAQ | E5: 4 | F5: 3.08 | G5: 26.6 | H5: 36.72 | I5: 31.689028 | J5: 131.73 | K5: 89.7 | L5: 100 | M5: 94.3 | N5: ⭐ Strong | O5: 🏆 Elite | P5: ⭐ Strong Buy | Q5: FULL
A6: 2 | B6: Motilal Oswal S&P 500 Index Fund - Regular Plan Growth | C6: Motilal Oswal Mutual Fund | D6: S&P 500 | E6: 3.08 | F6: 4.25 | G6: 18.48 | H6: 30.38 | I6: 25.610509 | J6: 102.13 | K6: 93 | L6: 50 | M6: 73.7 | N6: 🔥 Hot | O6: ➡️ Average | P6: 📈 Momentum Play | Q6: FULL
A7: 3 | B7: Motilal Oswal Nifty India Defence Index Fund Regular Plan Growth | C7: Motilal Oswal Mutual Fund | D7: Index Fund | E7: 6.68 | F7: 11.61 | G7: 21.49 | H7: 27.07 | I7: 17.392504 | J7: 0 | K7: 100 | L7: 0 | M7: 55 | N7: 🔥 Hot | O7: ⏳ New Fund | P7: 🔥 Hot Momentum | Q7: MOMENTUM_ONLY
A8: 3 | B8: Motilal Oswal Nifty Microcap 250 Index Fund- Regular- Growth Option | C8: Motilal Oswal Mutual Fund | D8: Index Fund | E8: 4.94 | F8: 14.96 | G8: 18.85 | H8: 12.52 | I8: 2.7180607 | J8: 69.86 | K8: 100 | L8: 0 | M8: 55 | N8: 🔥 Hot | O8: 🔴 Not Qualified | P8: ✅ Buy | Q8: FULL
A9: 5 | B9: Axis Nifty Smallcap 50 Index Fund - Regular Plan - Growth Option | C9: Axis Mutual Fund | D9: Index Fund | E9: 3.4 | F9: 12.21 | G9: 16.79 | H9: 15.83 | I9: 6.1367043 | J9: 81.37 | K9: 99.4 | L9: 0 | M9: 54.7 | N9: 🔥 Hot | O9: 🔴 Not Qualified | P9: ⚠️ Watch | Q9: FULL
A10: 6 | B10: Kotak Nifty Smallcap 50 Index Fund - Regular Plan - Growth | C10: Kotak Mahindra Mutual Fund | D10: Index Fund | E10: 3.42 | F10: 12.29 | G10: 16.63 | H10: 15.7 | I10: 6.3672882 | J10: 82.27 | K10: 99.3 | L10: 0 | M10: 54.6 | N10: 🔥 Hot | O10: 🔴 Not Qualified | P10: ⚠️ Watch | Q10: FULL
A11: 7 | B11: Bandhan Nifty Alpha 50 Index Fund - Regular Plan - Growth | C11: Bandhan Mutual Fund | D11: Index Fund | E11: 5.18 | F11: 9.25 | G11: 9.36 | H11: 11.2 | I11: -3.0928279 | J11: 0 | K11: 97.2 | L11: 0 | M11: 53.5 | N11: 🔥 Hot | O11: ⏳ New Fund | P11: 🔥 Hot Momentum | Q11: MOMENTUM_ONLY
A12: 8 | B12: Nippon India Nifty Auto Index Fund - Regular Plan- Growth Option | C12: Nippon India Mutual Fund | D12: Index Fund | E12: 8.22 | F12: 14.7 | G12: 4.01 | H12: 21.7 | I12: 0 | J12: 0 | K12: 94.6 | L12: 0 | M12: 52 | N12: 🔥 Hot | O12: ⏳ New Fund | P12: 🔥 Hot Momentum | Q12: MOMENTUM_ONLY
A13: 9 | B13: Edelweiss BSE Internet Economy Index Fund - Regular Plan - Growth | C13: Edelweiss Mutual Fund | D13: Index Fund | E13: 5.39 | F13: 9.39 | G13: 10.2 | H13: 6.51 | I13: 0 | J13: 0 | K13: 94.5 | L13: 0 | M13: 52 | N13: 🔥 Hot | O13: ⏳ New Fund | P13: 🔥 Hot Momentum | Q13: MOMENTUM_ONLY
A14: 10 | B14: Motilal Oswal Nifty MidSmall Healthcare Index Fund-Regular Plan-Growth | C14: Motilal Oswal Mutual Fund | D14: Pharma/Healthcare | E14: 2.75 | F14: 7.29 | G14: 21.16 | H14: 16.43 | I14: 0 | J14: 0 | K14: 94.4 | L14: 0 | M14: 51.9 | N14: 🔥 Hot | O14: ⏳ New Fund | P14: 🔥 Hot Momentum | Q14: MOMENTUM_ONLY
A15: 11 | B15: Tata Nifty500 Multicap India Manufacturing 50:30:20 Index Fund -Regular Plan-Growth | C15: Tata Mutual Fund | D15: Index Fund | E15: 3.67 | F15: 6.27 | G15: 6.53 | H15: 14.07 | I15: 5.2093152 | J15: 0 | K15: 94.4 | L15: 0 | M15: 51.9 | N15: 🔥 Hot | O15: ⏳ New Fund | P15: 🔥 Hot Momentum | Q15: MOMENTUM_ONLY
A16: 12 | B16: ICICI Prudential Nifty Auto Index Fund - Growth | C16: ICICI Prudential Mutual Fund | D16: Index Fund | E16: 8.22 | F16: 14.55 | G16: 3.78 | H16: 21.46 | I16: 6.9532608 | J16: 89.6 | K16: 94.3 | L16: 0 | M16: 51.8 | N16: 🔥 Hot | O16: 🔴 Not Qualified | P16: ⚠️ Watch | Q16: FULL
... A346: 0 | B346: UTI Nifty500 Shariah Index Fund - Regular Plan Growth Option | C346: UTI Mutual Fund | D346: Index Fund | E346: 1.76 | F346: 2.77 | G346: 0 | H346: 0 | I346: 0 | J346: 0 | K346: 0 | L346: 0 | M346: 0 | N346: ❌ N/A | O346: ❌ N/A | P346: ❌ Missing Data | Q346: MISSING

Sheet Other  Etfs
A1: ✦ OTHER ETFS ✦
A2: ="Dual Engine: 55% Momentum + 45% Quality | ✅ Full: "&COUNTIF(Q5:Q267,"FULL")&" | ⚠️ Momentum: "&COUNTIF(Q5:Q267,"MOMENTUM_ONLY")&" | ❌ Missing: "&COUNTIF(Q5:Q267,"MISSING")&" | Total: "&COUNTA(B5:B267)
E3: ◄ Momentum ► | H3: ◄ Long-Term ► | K3: ◄ Engine Scores ► | N3: ◄ Signals ►
A4: Rank | B4: Scheme Name | C4: AMC | D4: Asset Class | E4: 1M Return | F4: 3M Return | G4: 6M Return | H4: 1Y Return | I4: 2Y CAGR | J4: 3Y CAGR | K4: Engine 1 (Momentum) | L4: Engine 2 (Quality) | M4: Composite Score | N4: Momentum Signal | O4: Quality Signal | P4: Composite Signal | Q4: Data Status
A5: 1 | B5: Motilal Oswal Nasdaq Q50 ETF | C5: Motilal Oswal Mutual Fund | D5: NASDAQ | E5: 7.99 | F5: 15.68 | G5: 36.94 | H5: 59.1 | I5: 41.573303 | J5: 136.75 | K5: 100 | L5: 56.2 | M5: 80.3 | N5: 🔥 Hot | O5: ➡️ Average | P5: ⭐ Strong Buy | Q5: FULL
A6: 2 | B6: ICICI PRUDENTIAL SILVER ETF | C6: ICICI Prudential Mutual Fund | D6: Silver | E6: 8.18 | F6: -12.91 | G6: -1.6 | H6: 100.58 | I6: 67.119718 | J6: 220.82 | K6: 66.4 | L6: 97.2 | M6: 80.3 | N6: 📈 Good | O6: 🏆 Elite | P6: ⭐ Strong Buy | Q6: FULL
A7: 3 | B7: DSP Silver ETF | C7: DSP Mutual Fund | D7: Silver | E7: 8.24 | F7: -12.93 | G7: -1.68 | H7: 100.46 | I7: 66.967063 | J7: 219.8 | K7: 65.7 | L7: 88.1 | M7: 75.8 | N7: 📈 Good | O7: ⭐ Strong | P7: ⭐ Strong Buy | Q7: FULL
A8: 4 | B8: Axis Silver ETF | C8: Axis Mutual Fund | D8: Silver | E8: 8.09 | F8: -12.78 | G8: -1.6 | H8: 99.95 | I8: 66.868211 | J8: 220.72 | K8: 66 | L8: 85.9 | M8: 75 | N8: 📈 Good | O8: ⭐ Strong | P8: 🏛️ Quality Hold | Q8: FULL
A9: 5 | B9: HDFC Silver ETF - Growth Option | C9: HDFC Mutual Fund | D9: Silver | E9: 8.06 | F9: -12.88 | G9: -1.76 | H9: 99.5 | I9: 66.628329 | J9: 222.79 | K9: 64 | L9: 84.7 | M9: 73.3 | N9: 📈 Good | O9: ⭐ Strong | P9: 🏛️ Quality Hold | Q9: FULL
A10: 6 | B10: Mirae Asset Silver ETF | C10: Mirae Asset Mutual Fund | D10: Silver | E10: 8.09 | F10: -12.83 | G10: -1.63 | H10: 99.95 | I10: 66.790287 | J10: 219.24 | K10: 65.4 | L10: 78.4 | M10: 71.2 | N10: 📈 Good | O10: ⭐ Strong | P10: 🏛️ Quality Hold | Q10: FULL
A11: 7 | B11: Motilal Oswal Nasdaq 100 ETF (MOFN100) | C11: Motilal Oswal Mutual Fund | D11: NASDAQ | E11: 4.21 | F11: 3.27 | G11: 27.19 | H11: 37.59 | I11: 32.39713 | J11: 135.06 | K11: 85.1 | L11: 50 | M11: 69.3 | N11: ⭐ Strong | O11: ➡️ Average | P11: 📈 Momentum Play | Q11: FULL
A12: 8 | B12: Nippon India Silver ETF | C12: Nippon India Mutual Fund | D12: Silver | E12: 8.12 | F12: -12.91 | G12: -1.72 | H12: 99.82 | I12: 66.553295 | J12: 218.12 | K12: 64.9 | L12: 68.4 | M12: 66.5 | N12: 📈 Good | O12: 🏛️ Solid | P12: 🏛️ Quality Hold | Q12: FULL
A13: 9 | B13: UTI Silver Exchange Traded Fund | C13: UTI Mutual Fund | D13: Silver | E13: 8.1 | F13: -12.9 | G13: -1.08 | H13: 99.14 | I13: 66.613325 | J13: 214.96 | K13: 66 | L13: 64.4 | M13: 65.3 | N13: 📈 Good | O13: 🏛️ Solid | P13: 📈 Momentum Play | Q13: FULL
A14: 10 | B14: Mirae Asset S&P 500 Top 50 ETF | C14: Mirae Asset Mutual Fund | D14: S&P 500 | E14: 2.65 | F14: -0.99 | G14: 15.64 | H14: 24.44 | I14: 24.663547 | J14: 110.79 | K14: 73.4 | L14: 40 | M14: 58.4 | N14: 📈 Good | O14: ➡️ Average | P14: ✅ Buy | Q14: FULL
A15: 11 | B15: Motilal Oswal Nifty India Defence ETF | C15: Motilal Oswal Mutual Fund | D15: Index Fund | E15: 6.74 | F15: 11.79 | G15: 21.92 | H15: 27.89 | I15: 0 | J15: 0 | K15: 100 | L15: 0 | M15: 55 | N15: 🔥 Hot | O15: ⏳ New Fund | P15: 🔥 Hot Momentum | Q15: MOMENTUM_ONLY
A16: 12 | B16: Motilal Oswal BSE Healthcare ETF | C16: Motilal Oswal Mutual Fund | D16: Pharma/Healthcare | E16: 2.14 | F16: 7.15 | G16: 17.57 | H16: 14.67 | I16: 11.43608 | J16: 84.33 | K16: 87.1 | L16: 13.1 | M16: 53.8 | N16: ⭐ Strong | O16: ⚠️ Below Avg | P16: ⚠️ Watch | Q16: FULL
... A267: 0 | B267: ANGEL ONE SILVER ETF | C267: Angel One Mutual Fund | D267: Silver | E267: 8.94 | F267: -11.87 | G267: 0 | H267: 0 | I267: 0 | J267: 0 | K267: 0 | L267: 0 | M267: 0 | N267: ❌ N/A | O267: ❌ N/A | P267: ❌ Missing Data | Q267: MISSING

Sheet 📊 CONSOLIDATED
A1: 📊 CONSOLIDATED VIEW — ALL FUNDS RANKED
A2: ="All Funds Consolidated | 55% Momentum + 45% Quality | ✅ Full: "&COUNTIF($U:$U,"FULL")&" | ⚠️ Momentum: "&COUNTIF($U:$U,"MOMENTUM_ONLY")&" | ❌ Missing: "&COUNTIF($U:$U,"MISSING")&" | Total: "&COUNTA(B5:B799)
F3: ◄ Momentum ► | I3: ◄ Long-Term ► | L3: ◄ Engine Scores ► | O3: ◄ Rank in Asset Class ► | R3: ◄ Signals ►
A4: Rank | B4: Scheme Name | C4: AMC | D4: Category | E4: Asset Class | F4: 1M Return | G4: 3M Return | H4: 6M Return | I4: 1Y Return | J4: 2Y CAGR | K4: 3Y CAGR | L4: Engine 1 (Momentum) | M4: Engine 2 (Quality) | N4: Composite Score | O4: E1 Rank (in Asset) | P4: E2 Rank (in Asset) | Q4: Comp Rank (in Asset) | R4: Momentum Signal | S4: Quality Signal | T4: Composite Signal | U4: Data Status
A5: 1 | B5: ICICI Prudential NASDAQ 100 Index Fund - Growth | C5: ICICI Prudential Mutual Fund | D5: Index Funds | E5: NASDAQ | F5: 4 | G5: 3.08 | H5: 26.6 | I5: 36.72 | J5: 31.689028 | K5: 131.73 | L5: 89.7 | M5: 100 | N5: 94.3 | O5: =COUNTIFS($E:$E,$E5,$L:$L,">"&$L5)+1 | P5: =COUNTIFS($E:$E,$E5,$M:$M,">"&$M5)+1 | Q5: =COUNTIFS($E:$E,$E5,$N:$N,">"&$N5)+1 | R5: ⭐ Strong | S5: 🏆 Elite | T5: ⭐ Strong Buy | U5: FULL
A6: 2 | B6: Mirae Asset Global X Artificial Intelligence & Technology ETF Fund of Fund - Regular Plan - Growth | C6: Mirae Asset Mutual Fund | D6: Fof Overseas | E6: International | F6: 8.14 | G6: 5.08 | H6: 35.91 | I6: 54.1 | J6: 43.443369 | K6: 171.88 | L6: 91.4 | M6: 93.3 | N6: 92.2 | O6: =COUNTIFS($E:$E,$E6,$L:$L,">"&$L6)+1 | P6: =COUNTIFS($E:$E,$E6,$M:$M,">"&$M6)+1 | Q6: =COUNTIFS($E:$E,$E6,$N:$N,">"&$N6)+1 | R6: 🔥 Hot | S6: 🏆 Elite | T6: ⭐ Strong Buy | U6: FULL
A7: 3 | B7: ICICI Prudential Strategic Metal and Energy Equity Fund of Fund - Growth | C7: ICICI Prudential Mutual Fund | D7: Fof Overseas | E7: Commodities | F7: 13.94 | G7: 4.49 | H7: 14.37 | I7: 74.53 | J7: 45.14131 | K7: 145.47 | L7: 80.2 | M7: 94.9 | N7: 86.8 | O7: =COUNTIFS($E:$E,$E7,$L:$L,">"&$L7)+1 | P7: =COUNTIFS($E:$E,$E7,$M:$M,">"&$M7)+1 | Q7: =COUNTIFS($E:$E,$E7,$N:$N,">"&$N7)+1 | R7: ⭐ Strong | S7: 🏆 Elite | T7: ⭐ Strong Buy | U7: FULL
A8: 4 | B8: DSP World Mining Overseas Equity Omni FoF - Regular Plan - Growth | C8: DSP Mutual Fund | D8: Fof Overseas | E8: International | F8: 15.47 | G8: 4.8 | H8: 4.85 | I8: 77.44 | J8: 45.650266 | K8: 124.33 | L8: 71.5 | M8: 91.2 | N8: 80.3 | O8: =COUNTIFS($E:$E,$E8,$L:$L,">"&$L8)+1 | P8: =COUNTIFS($E:$E,$E8,$M:$M,">"&$M8)+1 | Q8: =COUNTIFS($E:$E,$E8,$N:$N,">"&$N8)+1 | R8: 📈 Good | S8: 🏆 Elite | T8: ⭐ Strong Buy | U8: FULL
A9: 5 | B9: Motilal Oswal Nasdaq Q50 ETF | C9: Motilal Oswal Mutual Fund | D9: Other Etfs | E9: NASDAQ | F9: 7.99 | G9: 15.68 | H9: 36.94 | I9: 59.1 | J9: 41.573303 | K9: 136.75 | L9: 100 | M9: 56.2 | N9: 80.3 | O9: =COUNTIFS($E:$E,$E9,$L:$L,">"&$L9)+1 | P9: =COUNTIFS($E:$E,$E9,$M:$M,">"&$M9)+1 | Q9: =COUNTIFS($E:$E,$E9,$N:$N,">"&$N9)+1 | R9: 🔥 Hot | S9: ➡️ Average | T9: ⭐ Strong Buy | U9: FULL
A10: 6 | B10: ICICI PRUDENTIAL SILVER ETF | C10: ICICI Prudential Mutual Fund | D10: Other Etfs | E10: Silver | F10: 8.18 | G10: -12.91 | H10: -1.6 | I10: 100.58 | J10: 67.119718 | K10: 220.82 | L10: 66.4 | M10: 97.2 | N10: 80.3 | O10: =COUNTIFS($E:$E,$E10,$L:$L,">"&$L10)+1 | P10: =COUNTIFS($E:$E,$E10,$M:$M,">"&$M10)+1 | Q10: =COUNTIFS($E:$E,$E10,$N:$N,">"&$N10)+1 | R10: 📈 Good | S10: 🏆 Elite | T10: ⭐ Strong Buy | U10: FULL
A11: 7 | B11: DSP World Gold Mining Overseas Equity Omni FoF - Regular Plan - Growth | C11: DSP Mutual Fund | D11: Fof Overseas | E11: Gold | F11: 26.45 | G11: 6.81 | H11: -4.09 | I11: 77.12 | J11: 68.127927 | K11: 287.35 | L11: 64.2 | M11: 99.4 | N11: 80 | O11: =COUNTIFS($E:$E,$E11,$L:$L,">"&$L11)+1 | P11: =COUNTIFS($E:$E,$E11,$M:$M,">"&$M11)+1 | Q11: =COUNTIFS($E:$E,$E11,$N:$N,">"&$N11)+1 | R11: 📈 Good | S11: 🏆 Elite | T11: ⭐ Strong Buy | U11: FULL
A12: 8 | B12: Kotak US Specific Equity Passive FOF - Regular Plan - Growth | C12: Kotak Mahindra Mutual Fund | D12: Fof Overseas | E12: Standard Equity/Debt | F12: 4.71 | G12: 4.11 | H12: 26.74 | I12: 37.91 | J12: 32.332914 | K12: 134.72 | L12: 77 | M12: 79.9 | N12: 78.3 | O12: =COUNTIFS($E:$E,$E12,$L:$L,">"&$L12)+1 | P12: =COUNTIFS($E:$E,$E12,$M:$M,">"&$M12)+1 | Q12: =COUNTIFS($E:$E,$E12,$N:$N,">"&$N12)+1 | R12: ⭐ Strong | S12: ⭐ Strong | T12: ⭐ Strong Buy | U12: FULL
A13: 9 | B13: Edelweiss Emerging Markets Opportunities Equity Offshore Fund - Regular Plan - Growth Option | C13: Edelweiss Mutual Fund | D13: Fof Overseas | E13: International | F13: 4.35 | G13: 3.24 | H13: 18.23 | I13: 56.11 | J13: 35.558106 | K13: 110.57 | L13: 73.3 | M13: 81.9 | N13: 77.2 | O13: =COUNTIFS($E:$E,$E13,$L:$L,">"&$L13)+1 | P13: =COUNTIFS($E:$E,$E13,$M:$M,">"&$M13)+1 | Q13: =COUNTIFS($E:$E,$E13,$N:$N,">"&$N13)+1 | R13: 📈 Good | S13: ⭐ Strong | T13: ⭐ Strong Buy | U13: FULL
A14: 10 | B14: Quantum Gold ETF | C14: Quantum Mutual Fund | D14: Gold Etf | E14: Gold | F14: 9.05 | G14: -3.16 | H14: 1.31 | I14: 52.76 | J14: 46.584447 | K14: 156.52 | L14: 66.1 | M14: 88.9 | N14: 76.3 | O14: =COUNTIFS($E:$E,$E14,$L:$L,">"&$L14)+1 | P14: =COUNTIFS($E:$E,$E14,$M:$M,">"&$M14)+1 | Q14: =COUNTIFS($E:$E,$E14,$N:$N,">"&$N14)+1 | R14: 📈 Good | S14: ⭐ Strong | T14: ⭐ Strong Buy | U14: FULL
A15: 11 | B15: DSP Silver ETF | C15: DSP Mutual Fund | D15: Other Etfs | E15: Silver | F15: 8.24 | G15: -12.93 | H15: -1.68 | I15: 100.46 | J15: 66.967063 | K15: 219.8 | L15: 65.7 | M15: 88.1 | N15: 75.8 | O15: =COUNTIFS($E:$E,$E15,$L:$L,">"&$L15)+1 | P15: =COUNTIFS($E:$E,$E15,$M:$M,">"&$M15)+1 | Q15: =COUNTIFS($E:$E,$E15,$N:$N,">"&$N15)+1 | R15: 📈 Good | S15: ⭐ Strong | T15: ⭐ Strong Buy | U15: FULL
A16: 12 | B16: Axis NASDAQ 100 US Specific Equity Passive FOF - Regular Plan - Growth | C16: Axis Mutual Fund | D16: Fof Overseas | E16: NASDAQ | F16: 4.68 | G16: 4.15 | H16: 26.34 | I16: 37.4 | J16: 31.78012 | K16: 131.89 | L16: 75 | M16: 76.5 | N16: 75.7 | O16: =COUNTIFS($E:$E,$E16,$L:$L,">"&$L16)+1 | P16: =COUNTIFS($E:$E,$E16,$M:$M,">"&$M16)+1 | Q16: =COUNTIFS($E:$E,$E16,$N:$N,">"&$N16)+1 | R16: ⭐ Strong | S16: ⭐ Strong | T16: ⭐ Strong Buy | U16: FULL
... A799: 795 | B799: Mirae Asset BSE India Defence ETF FOF - Regular Plan - Growth | C799: Mirae Asset Mutual Fund | D799: Fof Domestic | E799: Index Fund | F799: 7.14 | G799: 12.82 | H799: 0 | I799: 0 | J799: 0 | K799: 0 | L799: 0 | M799: 0 | N799: 0 | O799: =COUNTIFS($E:$E,$E799,$L:$L,">"&$L799)+1 | P799: =COUNTIFS($E:$E,$E799,$M:$M,">"&$M799)+1 | Q799: =COUNTIFS($E:$E,$E799,$N:$N,">"&$N799)+1 | R799: ❌ N/A | S799: ❌ N/A | T799: ❌ Missing Data | U799: MISSING
